 * Running on http://127.0.0.1:5000/ (Press CTRL+C to quit)
 * Restarting with stat
 * Debugger is active!
 * Debugger pin code: 103-070-263
 * Detected change in '/home/apollo/apache-tomcat-8.0.41/webapps/petitext/demo_python_9/petitext.py', reloading
 * Restarting with stat
 * Debugger is active!
 * Debugger pin code: 103-070-263
]0;IPython: petitext/demo_python_9 * Running on http://127.0.0.1:5000/ (Press CTRL+C to quit)
 * Restarting with stat
 * Debugger is active!
 * Debugger pin code: 103-070-263
]0;IPython: petitext/demo_python_9 * Running on http://0.0.0.0:5000/ (Press CTRL+C to quit)
212.194.120.65 - - [13/Jun/2017 17:02:51] "POST /login HTTP/1.1" 302 -
[2017-06-13 17:02:51,250] ERROR in app: Exception on /result [GET]
Traceback (most recent call last):
  File "/home/Anaconda2/lib/python2.7/site-packages/flask/app.py", line 1982, in wsgi_app
    response = self.full_dispatch_request()
  File "/home/Anaconda2/lib/python2.7/site-packages/flask/app.py", line 1614, in full_dispatch_request
    rv = self.handle_user_exception(e)
  File "/home/Anaconda2/lib/python2.7/site-packages/flask/app.py", line 1517, in handle_user_exception
    reraise(exc_type, exc_value, tb)
  File "/home/Anaconda2/lib/python2.7/site-packages/flask/app.py", line 1612, in full_dispatch_request
    rv = self.dispatch_request()
  File "/home/Anaconda2/lib/python2.7/site-packages/flask/app.py", line 1598, in dispatch_request
    return self.view_functions[rule.endpoint](**req.view_args)
  File "/home/apollo/apache-tomcat-8.0.41/webapps/petitext/demo_python_9/petitext.py", line 81, in generer_tous_arbres
    print("# Fait ##############" + datum + "###############")
UnicodeEncodeError: 'ascii' codec can't encode character u'\xe9' in position 36: ordinal not in range(128)
212.194.120.65 - - [13/Jun/2017 17:02:51] "GET /result?newLine=&filePath=.%2Fdefinition+de+famille+%28simple%29.txt HTTP/1.1" 500 -
212.194.120.65 - - [13/Jun/2017 17:02:51] "GET /favicon.ico HTTP/1.1" 404 -
212.194.120.65 - - [13/Jun/2017 17:03:01] "POST /login HTTP/1.1" 302 -
[2017-06-13 17:03:01,852] ERROR in app: Exception on /result [GET]
Traceback (most recent call last):
  File "/home/Anaconda2/lib/python2.7/site-packages/flask/app.py", line 1982, in wsgi_app
    response = self.full_dispatch_request()
  File "/home/Anaconda2/lib/python2.7/site-packages/flask/app.py", line 1614, in full_dispatch_request
    rv = self.handle_user_exception(e)
  File "/home/Anaconda2/lib/python2.7/site-packages/flask/app.py", line 1517, in handle_user_exception
    reraise(exc_type, exc_value, tb)
  File "/home/Anaconda2/lib/python2.7/site-packages/flask/app.py", line 1612, in full_dispatch_request
    rv = self.dispatch_request()
  File "/home/Anaconda2/lib/python2.7/site-packages/flask/app.py", line 1598, in dispatch_request
    return self.view_functions[rule.endpoint](**req.view_args)
  File "/home/apollo/apache-tomcat-8.0.41/webapps/petitext/demo_python_9/petitext.py", line 81, in generer_tous_arbres
    print("# Fait ##############" + datum + "###############")
UnicodeEncodeError: 'ascii' codec can't encode character u'\xe9' in position 36: ordinal not in range(128)
212.194.120.65 - - [13/Jun/2017 17:03:01] "GET /result?newLine=&filePath=.%2Fdefinition+de+famille+%28simple%29.txt HTTP/1.1" 500 -
212.194.120.65 - - [13/Jun/2017 17:03:22] "POST /login HTTP/1.1" 302 -
[2017-06-13 17:03:22,574] ERROR in app: Exception on /result [GET]
Traceback (most recent call last):
  File "/home/Anaconda2/lib/python2.7/site-packages/flask/app.py", line 1982, in wsgi_app
    response = self.full_dispatch_request()
  File "/home/Anaconda2/lib/python2.7/site-packages/flask/app.py", line 1614, in full_dispatch_request
    rv = self.handle_user_exception(e)
  File "/home/Anaconda2/lib/python2.7/site-packages/flask/app.py", line 1517, in handle_user_exception
    reraise(exc_type, exc_value, tb)
  File "/home/Anaconda2/lib/python2.7/site-packages/flask/app.py", line 1612, in full_dispatch_request
    rv = self.dispatch_request()
  File "/home/Anaconda2/lib/python2.7/site-packages/flask/app.py", line 1598, in dispatch_request
    return self.view_functions[rule.endpoint](**req.view_args)
  File "/home/apollo/apache-tomcat-8.0.41/webapps/petitext/demo_python_9/petitext.py", line 81, in generer_tous_arbres
    print("# Fait ##############" + datum + "###############")
UnicodeEncodeError: 'ascii' codec can't encode character u'\xe9' in position 36: ordinal not in range(128)
212.194.120.65 - - [13/Jun/2017 17:03:22] "GET /result?newLine=&filePath=.%2Fdefinition+de+famille+%28simple%29.txt HTTP/1.1" 500 -
 * Running on http://0.0.0.0:5000/ (Press CTRL+C to quit)
212.194.120.65 - - [13/Jun/2017 17:04:02] "POST /login HTTP/1.1" 302 -
[2017-06-13 17:04:02,566] ERROR in app: Exception on /result [GET]
Traceback (most recent call last):
  File "/home/Anaconda2/lib/python2.7/site-packages/flask/app.py", line 1982, in wsgi_app
    response = self.full_dispatch_request()
  File "/home/Anaconda2/lib/python2.7/site-packages/flask/app.py", line 1614, in full_dispatch_request
    rv = self.handle_user_exception(e)
  File "/home/Anaconda2/lib/python2.7/site-packages/flask/app.py", line 1517, in handle_user_exception
    reraise(exc_type, exc_value, tb)
  File "/home/Anaconda2/lib/python2.7/site-packages/flask/app.py", line 1612, in full_dispatch_request
    rv = self.dispatch_request()
  File "/home/Anaconda2/lib/python2.7/site-packages/flask/app.py", line 1598, in dispatch_request
    return self.view_functions[rule.endpoint](**req.view_args)
  File "/home/apollo/apache-tomcat-8.0.41/webapps/petitext/demo_python_9/petitext.py", line 81, in generer_tous_arbres
    print("# Fait ##############" + datum + "###############")
UnicodeEncodeError: 'ascii' codec can't encode character u'\xe9' in position 36: ordinal not in range(128)
212.194.120.65 - - [13/Jun/2017 17:04:02] "GET /result?newLine=&filePath=.%2Fdefinition+de+famille+%28simple%29.txt HTTP/1.1" 500 -
212.194.120.65 - - [13/Jun/2017 17:04:05] "POST /login HTTP/1.1" 302 -
[2017-06-13 17:04:05,480] ERROR in app: Exception on /result [GET]
Traceback (most recent call last):
  File "/home/Anaconda2/lib/python2.7/site-packages/flask/app.py", line 1982, in wsgi_app
    response = self.full_dispatch_request()
  File "/home/Anaconda2/lib/python2.7/site-packages/flask/app.py", line 1614, in full_dispatch_request
    rv = self.handle_user_exception(e)
  File "/home/Anaconda2/lib/python2.7/site-packages/flask/app.py", line 1517, in handle_user_exception
    reraise(exc_type, exc_value, tb)
  File "/home/Anaconda2/lib/python2.7/site-packages/flask/app.py", line 1612, in full_dispatch_request
    rv = self.dispatch_request()
  File "/home/Anaconda2/lib/python2.7/site-packages/flask/app.py", line 1598, in dispatch_request
    return self.view_functions[rule.endpoint](**req.view_args)
  File "/home/apollo/apache-tomcat-8.0.41/webapps/petitext/demo_python_9/petitext.py", line 81, in generer_tous_arbres
    print("# Fait ##############" + datum + "###############")
UnicodeEncodeError: 'ascii' codec can't encode character u'\xe9' in position 36: ordinal not in range(128)
212.194.120.65 - - [13/Jun/2017 17:04:05] "GET /result?newLine=&filePath=.%2Fdefinition+de+famille+%28simple%29.txt HTTP/1.1" 500 -
[2017-06-13 17:04:13,369] ERROR in app: Exception on /result [GET]
Traceback (most recent call last):
  File "/home/Anaconda2/lib/python2.7/site-packages/flask/app.py", line 1982, in wsgi_app
    response = self.full_dispatch_request()
  File "/home/Anaconda2/lib/python2.7/site-packages/flask/app.py", line 1614, in full_dispatch_request
    rv = self.handle_user_exception(e)
  File "/home/Anaconda2/lib/python2.7/site-packages/flask/app.py", line 1517, in handle_user_exception
    reraise(exc_type, exc_value, tb)
  File "/home/Anaconda2/lib/python2.7/site-packages/flask/app.py", line 1612, in full_dispatch_request
    rv = self.dispatch_request()
  File "/home/Anaconda2/lib/python2.7/site-packages/flask/app.py", line 1598, in dispatch_request
    return self.view_functions[rule.endpoint](**req.view_args)
  File "/home/apollo/apache-tomcat-8.0.41/webapps/petitext/demo_python_9/petitext.py", line 81, in generer_tous_arbres
    print("# Fait ##############" + datum + "###############")
UnicodeEncodeError: 'ascii' codec can't encode character u'\xe9' in position 36: ordinal not in range(128)
212.194.120.65 - - [13/Jun/2017 17:04:13] "GET /result?newLine=&filePath=.%2Fdefinition+de+famille+%28simple%29.txt HTTP/1.1" 500 -
[2017-06-13 17:04:14,453] ERROR in app: Exception on /result [GET]
Traceback (most recent call last):
  File "/home/Anaconda2/lib/python2.7/site-packages/flask/app.py", line 1982, in wsgi_app
    response = self.full_dispatch_request()
  File "/home/Anaconda2/lib/python2.7/site-packages/flask/app.py", line 1614, in full_dispatch_request
    rv = self.handle_user_exception(e)
  File "/home/Anaconda2/lib/python2.7/site-packages/flask/app.py", line 1517, in handle_user_exception
    reraise(exc_type, exc_value, tb)
  File "/home/Anaconda2/lib/python2.7/site-packages/flask/app.py", line 1612, in full_dispatch_request
    rv = self.dispatch_request()
  File "/home/Anaconda2/lib/python2.7/site-packages/flask/app.py", line 1598, in dispatch_request
    return self.view_functions[rule.endpoint](**req.view_args)
  File "/home/apollo/apache-tomcat-8.0.41/webapps/petitext/demo_python_9/petitext.py", line 81, in generer_tous_arbres
    print("# Fait ##############" + datum + "###############")
UnicodeEncodeError: 'ascii' codec can't encode character u'\xe9' in position 36: ordinal not in range(128)
212.194.120.65 - - [13/Jun/2017 17:04:14] "GET /result?newLine=&filePath=.%2Fdefinition+de+famille+%28simple%29.txt HTTP/1.1" 500 -
[2017-06-13 17:04:15,161] ERROR in app: Exception on /result [GET]
Traceback (most recent call last):
  File "/home/Anaconda2/lib/python2.7/site-packages/flask/app.py", line 1982, in wsgi_app
    response = self.full_dispatch_request()
  File "/home/Anaconda2/lib/python2.7/site-packages/flask/app.py", line 1614, in full_dispatch_request
    rv = self.handle_user_exception(e)
  File "/home/Anaconda2/lib/python2.7/site-packages/flask/app.py", line 1517, in handle_user_exception
    reraise(exc_type, exc_value, tb)
  File "/home/Anaconda2/lib/python2.7/site-packages/flask/app.py", line 1612, in full_dispatch_request
    rv = self.dispatch_request()
  File "/home/Anaconda2/lib/python2.7/site-packages/flask/app.py", line 1598, in dispatch_request
    return self.view_functions[rule.endpoint](**req.view_args)
  File "/home/apollo/apache-tomcat-8.0.41/webapps/petitext/demo_python_9/petitext.py", line 81, in generer_tous_arbres
    print("# Fait ##############" + datum + "###############")
UnicodeEncodeError: 'ascii' codec can't encode character u'\xe9' in position 36: ordinal not in range(128)
212.194.120.65 - - [13/Jun/2017 17:04:15] "GET /result?newLine=&filePath=.%2Fdefinition+de+famille+%28simple%29.txt HTTP/1.1" 500 -
 * Running on http://0.0.0.0:5000/ (Press CTRL+C to quit)
212.194.120.65 - - [14/Jun/2017 11:51:54] "POST /login HTTP/1.1" 302 -
[2017-06-14 11:51:54,267] ERROR in app: Exception on /result [GET]
Traceback (most recent call last):
  File "/home/Anaconda2/lib/python2.7/site-packages/flask/app.py", line 1982, in wsgi_app
    response = self.full_dispatch_request()
  File "/home/Anaconda2/lib/python2.7/site-packages/flask/app.py", line 1614, in full_dispatch_request
    rv = self.handle_user_exception(e)
  File "/home/Anaconda2/lib/python2.7/site-packages/flask/app.py", line 1517, in handle_user_exception
    reraise(exc_type, exc_value, tb)
  File "/home/Anaconda2/lib/python2.7/site-packages/flask/app.py", line 1612, in full_dispatch_request
    rv = self.dispatch_request()
  File "/home/Anaconda2/lib/python2.7/site-packages/flask/app.py", line 1598, in dispatch_request
    return self.view_functions[rule.endpoint](**req.view_args)
  File "/home/apollo/apache-tomcat-8.0.41/webapps/petitext/demo_python_9/petitext.py", line 81, in generer_tous_arbres
    print("# Fait ##############" + datum + "###############")
UnicodeEncodeError: 'ascii' codec can't encode character u'\xe9' in position 36: ordinal not in range(128)
212.194.120.65 - - [14/Jun/2017 11:51:54] "GET /result?newLine=&filePath=.%2Fdefinition+de+famille+%28simple%29.txt HTTP/1.1" 500 -
212.194.120.65 - - [14/Jun/2017 11:51:54] "GET /favicon.ico HTTP/1.1" 404 -
212.194.120.65 - - [14/Jun/2017 11:53:18] "POST /login HTTP/1.1" 302 -
[2017-06-14 11:53:18,775] ERROR in app: Exception on /result [GET]
Traceback (most recent call last):
  File "/home/Anaconda2/lib/python2.7/site-packages/flask/app.py", line 1982, in wsgi_app
    response = self.full_dispatch_request()
  File "/home/Anaconda2/lib/python2.7/site-packages/flask/app.py", line 1614, in full_dispatch_request
    rv = self.handle_user_exception(e)
  File "/home/Anaconda2/lib/python2.7/site-packages/flask/app.py", line 1517, in handle_user_exception
    reraise(exc_type, exc_value, tb)
  File "/home/Anaconda2/lib/python2.7/site-packages/flask/app.py", line 1612, in full_dispatch_request
    rv = self.dispatch_request()
  File "/home/Anaconda2/lib/python2.7/site-packages/flask/app.py", line 1598, in dispatch_request
    return self.view_functions[rule.endpoint](**req.view_args)
  File "/home/apollo/apache-tomcat-8.0.41/webapps/petitext/demo_python_9/petitext.py", line 81, in generer_tous_arbres
    print("# Fait ##############" + datum + "###############")
UnicodeEncodeError: 'ascii' codec can't encode character u'\xe9' in position 36: ordinal not in range(128)
212.194.120.65 - - [14/Jun/2017 11:53:18] "GET /result?newLine=&filePath=.%2Fdefinition+de+famille+%28simple%29.txt HTTP/1.1" 500 -
 * Running on http://0.0.0.0:5000/ (Press CTRL+C to quit)
 * Running on http://0.0.0.0:5000/ (Press CTRL+C to quit)
 * Running on http://51.255.77.152:5000/ (Press CTRL+C to quit)
212.194.120.65 - - [14/Jun/2017 12:07:03] "POST /login HTTP/1.1" 302 -
[2017-06-14 12:07:03,769] ERROR in app: Exception on /result [GET]
Traceback (most recent call last):
  File "/home/Anaconda2/lib/python2.7/site-packages/flask/app.py", line 1982, in wsgi_app
    response = self.full_dispatch_request()
  File "/home/Anaconda2/lib/python2.7/site-packages/flask/app.py", line 1614, in full_dispatch_request
    rv = self.handle_user_exception(e)
  File "/home/Anaconda2/lib/python2.7/site-packages/flask/app.py", line 1517, in handle_user_exception
    reraise(exc_type, exc_value, tb)
  File "/home/Anaconda2/lib/python2.7/site-packages/flask/app.py", line 1612, in full_dispatch_request
    rv = self.dispatch_request()
  File "/home/Anaconda2/lib/python2.7/site-packages/flask/app.py", line 1598, in dispatch_request
    return self.view_functions[rule.endpoint](**req.view_args)
  File "/home/apollo/apache-tomcat-8.0.41/webapps/petitext/demo_python_9/petitext.py", line 81, in generer_tous_arbres
    print("# Fait ##############" + datum + "###############")
UnicodeEncodeError: 'ascii' codec can't encode character u'\xe9' in position 36: ordinal not in range(128)
212.194.120.65 - - [14/Jun/2017 12:07:03] "GET /result?newLine=&filePath=.%2Fdefinition+de+famille+%28simple%29.txt HTTP/1.1" 500 -
]0;IPython: petitext/demo_python_9[0;31m[0m
[0;31merror[0mTraceback (most recent call last)
[0;32m/home/apollo/apache-tomcat-8.0.41/webapps/petitext/demo_python_9/petitext.py[0m in [0;36m<module>[0;34m()[0m
[1;32m    154[0m [0;34m[0m[0m
[1;32m    155[0m [0;32mif[0m [0m__name__[0m [0;34m==[0m [0;34m'__main__'[0m[0;34m:[0m[0;34m[0m[0m
[0;32m--> 156[0;31m     [0mapp[0m[0;34m.[0m[0mrun[0m[0;34m([0m[0mhost[0m[0;34m=[0m[0;34m'51.255.77.152'[0m[0;34m,[0m [0mport[0m[0;34m=[0m[0;36m5000[0m[0;34m)[0m[0;34m[0m[0m
[0m
[0;32m/home/Anaconda2/lib/python2.7/site-packages/flask/app.pyc[0m in [0;36mrun[0;34m(self, host, port, debug, **options)[0m
[1;32m    839[0m         [0moptions[0m[0;34m.[0m[0msetdefault[0m[0;34m([0m[0;34m'use_debugger'[0m[0;34m,[0m [0mself[0m[0;34m.[0m[0mdebug[0m[0;34m)[0m[0;34m[0m[0m
[1;32m    840[0m         [0;32mtry[0m[0;34m:[0m[0;34m[0m[0m
[0;32m--> 841[0;31m             [0mrun_simple[0m[0;34m([0m[0mhost[0m[0;34m,[0m [0mport[0m[0;34m,[0m [0mself[0m[0;34m,[0m [0;34m**[0m[0moptions[0m[0;34m)[0m[0;34m[0m[0m
[0m[1;32m    842[0m         [0;32mfinally[0m[0;34m:[0m[0;34m[0m[0m
[1;32m    843[0m             [0;31m# reset the first request information if the development server[0m[0;34m[0m[0;34m[0m[0m

[0;32m/home/Anaconda2/lib/python2.7/site-packages/werkzeug/serving.pyc[0m in [0;36mrun_simple[0;34m(hostname, port, application, use_reloader, use_debugger, use_evalex, extra_files, reloader_interval, reloader_type, threaded, processes, request_handler, static_files, passthrough_errors, ssl_context)[0m
[1;32m    706[0m                           reloader_type)
[1;32m    707[0m     [0;32melse[0m[0;34m:[0m[0;34m[0m[0m
[0;32m--> 708[0;31m         [0minner[0m[0;34m([0m[0;34m)[0m[0;34m[0m[0m
[0m[1;32m    709[0m [0;34m[0m[0m
[1;32m    710[0m [0;34m[0m[0m

[0;32m/home/Anaconda2/lib/python2.7/site-packages/werkzeug/serving.pyc[0m in [0;36minner[0;34m()[0m
[1;32m    668[0m                           [0mprocesses[0m[0;34m,[0m [0mrequest_handler[0m[0;34m,[0m[0;34m[0m[0m
[1;32m    669[0m                           [0mpassthrough_errors[0m[0;34m,[0m [0mssl_context[0m[0;34m,[0m[0;34m[0m[0m
[0;32m--> 670[0;31m                           fd=fd)
[0m[1;32m    671[0m         [0;32mif[0m [0mfd[0m [0;32mis[0m [0mNone[0m[0;34m:[0m[0;34m[0m[0m
[1;32m    672[0m             [0mlog_startup[0m[0;34m([0m[0msrv[0m[0;34m.[0m[0msocket[0m[0;34m)[0m[0;34m[0m[0m

[0;32m/home/Anaconda2/lib/python2.7/site-packages/werkzeug/serving.pyc[0m in [0;36mmake_server[0;34m(host, port, app, threaded, processes, request_handler, passthrough_errors, ssl_context, fd)[0m
[1;32m    562[0m     [0;32melse[0m[0;34m:[0m[0;34m[0m[0m
[1;32m    563[0m         return BaseWSGIServer(host, port, app, request_handler,
[0;32m--> 564[0;31m                               passthrough_errors, ssl_context, fd=fd)
[0m[1;32m    565[0m [0;34m[0m[0m
[1;32m    566[0m [0;34m[0m[0m

[0;32m/home/Anaconda2/lib/python2.7/site-packages/werkzeug/serving.pyc[0m in [0;36m__init__[0;34m(self, host, port, app, handler, passthrough_errors, ssl_context, fd)[0m
[1;32m    474[0m                                       socket.SOCK_STREAM)
[1;32m    475[0m             [0mport[0m [0;34m=[0m [0;36m0[0m[0;34m[0m[0m
[0;32m--> 476[0;31m         [0mHTTPServer[0m[0;34m.[0m[0m__init__[0m[0;34m([0m[0mself[0m[0;34m,[0m [0;34m([0m[0mhost[0m[0;34m,[0m [0mint[0m[0;34m([0m[0mport[0m[0;34m)[0m[0;34m)[0m[0;34m,[0m [0mhandler[0m[0;34m)[0m[0;34m[0m[0m
[0m[1;32m    477[0m         [0mself[0m[0;34m.[0m[0mapp[0m [0;34m=[0m [0mapp[0m[0;34m[0m[0m
[1;32m    478[0m         [0mself[0m[0;34m.[0m[0mpassthrough_errors[0m [0;34m=[0m [0mpassthrough_errors[0m[0;34m[0m[0m

[0;32m/home/Anaconda2/lib/python2.7/SocketServer.pyc[0m in [0;36m__init__[0;34m(self, server_address, RequestHandlerClass, bind_and_activate)[0m
[1;32m    415[0m         [0;32mif[0m [0mbind_and_activate[0m[0;34m:[0m[0;34m[0m[0m
[1;32m    416[0m             [0;32mtry[0m[0;34m:[0m[0;34m[0m[0m
[0;32m--> 417[0;31m                 [0mself[0m[0;34m.[0m[0mserver_bind[0m[0;34m([0m[0;34m)[0m[0;34m[0m[0m
[0m[1;32m    418[0m                 [0mself[0m[0;34m.[0m[0mserver_activate[0m[0;34m([0m[0;34m)[0m[0;34m[0m[0m
[1;32m    419[0m             [0;32mexcept[0m[0;34m:[0m[0;34m[0m[0m

[0;32m/home/Anaconda2/lib/python2.7/BaseHTTPServer.pyc[0m in [0;36mserver_bind[0;34m(self)[0m
[1;32m    106[0m     [0;32mdef[0m [0mserver_bind[0m[0;34m([0m[0mself[0m[0;34m)[0m[0;34m:[0m[0;34m[0m[0m
[1;32m    107[0m         [0;34m"""Override server_bind to store the server name."""[0m[0;34m[0m[0m
[0;32m--> 108[0;31m         [0mSocketServer[0m[0;34m.[0m[0mTCPServer[0m[0;34m.[0m[0mserver_bind[0m[0;34m([0m[0mself[0m[0;34m)[0m[0;34m[0m[0m
[0m[1;32m    109[0m         [0mhost[0m[0;34m,[0m [0mport[0m [0;34m=[0m [0mself[0m[0;34m.[0m[0msocket[0m[0;34m.[0m[0mgetsockname[0m[0;34m([0m[0;34m)[0m[0;34m[[0m[0;34m:[0m[0;36m2[0m[0;34m][0m[0;34m[0m[0m
[1;32m    110[0m         [0mself[0m[0;34m.[0m[0mserver_name[0m [0;34m=[0m [0msocket[0m[0;34m.[0m[0mgetfqdn[0m[0;34m([0m[0mhost[0m[0;34m)[0m[0;34m[0m[0m

[0;32m/home/Anaconda2/lib/python2.7/SocketServer.pyc[0m in [0;36mserver_bind[0;34m(self)[0m
[1;32m    429[0m         [0;32mif[0m [0mself[0m[0;34m.[0m[0mallow_reuse_address[0m[0;34m:[0m[0;34m[0m[0m
[1;32m    430[0m             [0mself[0m[0;34m.[0m[0msocket[0m[0;34m.[0m[0msetsockopt[0m[0;34m([0m[0msocket[0m[0;34m.[0m[0mSOL_SOCKET[0m[0;34m,[0m [0msocket[0m[0;34m.[0m[0mSO_REUSEADDR[0m[0;34m,[0m [0;36m1[0m[0;34m)[0m[0;34m[0m[0m
[0;32m--> 431[0;31m         [0mself[0m[0;34m.[0m[0msocket[0m[0;34m.[0m[0mbind[0m[0;34m([0m[0mself[0m[0;34m.[0m[0mserver_address[0m[0;34m)[0m[0;34m[0m[0m
[0m[1;32m    432[0m         [0mself[0m[0;34m.[0m[0mserver_address[0m [0;34m=[0m [0mself[0m[0;34m.[0m[0msocket[0m[0;34m.[0m[0mgetsockname[0m[0;34m([0m[0;34m)[0m[0;34m[0m[0m
[1;32m    433[0m [0;34m[0m[0m

[0;32m/home/Anaconda2/lib/python2.7/socket.pyc[0m in [0;36mmeth[0;34m(name, self, *args)[0m
[1;32m    226[0m [0;34m[0m[0m
[1;32m    227[0m [0;32mdef[0m [0mmeth[0m[0;34m([0m[0mname[0m[0;34m,[0m[0mself[0m[0;34m,[0m[0;34m*[0m[0margs[0m[0;34m)[0m[0;34m:[0m[0;34m[0m[0m
[0;32m--> 228[0;31m     [0;32mreturn[0m [0mgetattr[0m[0;34m([0m[0mself[0m[0;34m.[0m[0m_sock[0m[0;34m,[0m[0mname[0m[0;34m)[0m[0;34m([0m[0;34m*[0m[0margs[0m[0;34m)[0m[0;34m[0m[0m
[0m[1;32m    229[0m [0;34m[0m[0m
[1;32m    230[0m [0;32mfor[0m [0m_m[0m [0;32min[0m [0m_socketmethods[0m[0;34m:[0m[0;34m[0m[0m

[0;31merror[0m: [Errno 98] Address already in use
212.194.120.65 - - [14/Jun/2017 12:08:00] "POST /login HTTP/1.1" 302 -
[2017-06-14 12:08:00,399] ERROR in app: Exception on /result [GET]
Traceback (most recent call last):
  File "/home/Anaconda2/lib/python2.7/site-packages/flask/app.py", line 1982, in wsgi_app
    response = self.full_dispatch_request()
  File "/home/Anaconda2/lib/python2.7/site-packages/flask/app.py", line 1614, in full_dispatch_request
    rv = self.handle_user_exception(e)
  File "/home/Anaconda2/lib/python2.7/site-packages/flask/app.py", line 1517, in handle_user_exception
    reraise(exc_type, exc_value, tb)
  File "/home/Anaconda2/lib/python2.7/site-packages/flask/app.py", line 1612, in full_dispatch_request
    rv = self.dispatch_request()
  File "/home/Anaconda2/lib/python2.7/site-packages/flask/app.py", line 1598, in dispatch_request
    return self.view_functions[rule.endpoint](**req.view_args)
  File "/home/apollo/apache-tomcat-8.0.41/webapps/petitext/demo_python_9/petitext.py", line 81, in generer_tous_arbres
    print("# Fait ##############" + datum + "###############")
UnicodeEncodeError: 'ascii' codec can't encode character u'\xe9' in position 36: ordinal not in range(128)
212.194.120.65 - - [14/Jun/2017 12:08:00] "GET /result?newLine=&filePath=.%2Fdefinition+de+famille+%28simple%29.txt HTTP/1.1" 500 -
212.194.120.65 - - [14/Jun/2017 12:08:00] "GET /favicon.ico HTTP/1.1" 404 -
